Workbook

Sheet Drugs To Order
B1: file | D1: ligand_name | E1: smiles | F1: Does Ari Like? | G1: Comments | H1: Does Summer Like? | I1: Comments | J1: Final Thoughts/Selection? | K1: Comments | L1: cLogp | M1: anchor | N1: ddg | O1: total_motifs | P1: significant_motifs | Q1: real_motif_ratio | R1: hbond_motif_count | S1: hbond_motif_energy_sum | T1: closest_autodock_recovery_rmsd | U1: closest_autodock_recovery_ddg | V1: strain_energy | W1: total
A2: cp | B2: ../../all/res122/res122_7F16_receptor_only_PV-003476110573_20_3.pdb | C2: /pi/summer.thyme-umw/rosetta_discovery_space/pth2/shapedb_results/refined_conformers/3_30_26_top_hits_to_investigate_hbonds/best_hits_review_4_6_26/122 | D2: PV-003476110573 | E2: c1(n(nc([C@H](CCC)C)n1)C1CC1)c1ccc2ncn(C)c(=O)c2c1 | F2: maybe | G2: probably reject over how it hits arg160 and asn402 | H2: yes | J2: yes | K2: lean toward keeping | L2: 3.4305 | M2: none | N2: -15.535781 | O2: 9 | P2: 3 | Q2: 0.444444 | R2: 2 | S2: -1.719191 | T2: 100 | U2: 0 | V2: 0 | W2: 97.189472
A3: cp | B3: ../../all/res122/res122_7F16_receptor_only_PV-004506718703_31_1.pdb | C3: /pi/summer.thyme-umw/rosetta_discovery_space/pth2/shapedb_results/refined_conformers/3_30_26_top_hits_to_investigate_hbonds/best_hits_review_4_6_26/122 | D3: PV-004506718703 | E3: [C@H]1(NC(=O)Cc2nonc2C)CN(C(=O)c2c(C)n(C)c3ccccc23)C[C@H]1C | F3: maybe | G3: misses res122 but pose looks not terrible | H3: decent | J3: yes | K3: lean toward keeping | L3: 1.99754 | M3: none | N3: -15.296063 | O3: 8 | P3: 3 | Q3: 0.25 | R3: 2 | S3: -1.293353 | T3: 100 | U3: 0 | V3: 0 | W3: 96.660584
A4: cp | B4: ../../all/res122/res122_7F16_receptor_only_PV-004655902680_26_5.pdb | C4: /pi/summer.thyme-umw/rosetta_discovery_space/pth2/shapedb_results/refined_conformers/3_30_26_top_hits_to_investigate_hbonds/best_hits_review_4_6_26/122 | D4: PV-004655902680 | E4: C1[C@@H](N(CCCN1C(=O)c1c(cc(C)[nH]1)C)C(=O)[C@@H]1CCOC1)c1ccccc1 | F4: decent | G4: can carbonyl point into tyrosine like into a benzene? | H4: yes | J4: yes | K4: risky, but lean towards keeping | L4: 3.08384 | M4: none | N4: -15.950047 | O4: 7 | P4: 3 | Q4: 0.285714 | R4: 3 | S4: -1.505897 | T4: 100 | U4: 0 | V4: 0 | W4: 95.82977
A5: cp | B5: ../../all/res122/res122_7F16_receptor_only_PV-005424082445_136_0.pdb | C5: /pi/summer.thyme-umw/rosetta_discovery_space/pth2/shapedb_results/refined_conformers/3_30_26_top_hits_to_investigate_hbonds/best_hits_review_4_6_26/122 | D5: PV-005424082445 | E5: [C@@H]1(CCN(C(=O)Cc2cnccc2OC)[C@@H]1C)NC(=O)Cc1cc(C)cc(C)c1 | F5: maybe | H5: decent | J5: yes | K5: isn't amazing, but diverse placement | L5: 2.59784 | M5: none | N5: -15.040718 | O5: 6 | P5: 3 | Q5: 0.333333 | R5: 2 | S5: -1.138986 | T5: 100 | U5: 0 | V5: 0 | W5: 95.153629
A6: cp | B6: ../../all/res122/res122_7F16_receptor_only_PV-005510814641_23_0.pdb | C6: /pi/summer.thyme-umw/rosetta_discovery_space/pth2/shapedb_results/refined_conformers/3_30_26_top_hits_to_investigate_hbonds/best_hits_review_4_6_26/122 | D6: PV-005510814641 | E6: C1N(CCCC[C@H]1N(C(=O)c1c(c(C)[nH]n1)F)C)C(=O)CCS(=O)(=O)C | F6: decent | G6: I like all the intereactions and maybe tyr188 could work | H6: yes | J6: yes | K6: little floppy, but lots of good interactions | L6: 0.74502 | M6: none | N6: -15.260381 | O6: 8 | P6: 3 | Q6: 0.25 | R6: 3 | S6: -1.428861 | T6: 100 | U6: 0 | V6: 0 | W6: 97.560758
A7: cp | B7: ../../all/res122/res122_7F16_receptor_only_PV-005890621085_19_0.pdb | C7: /pi/summer.thyme-umw/rosetta_discovery_space/pth2/shapedb_results/refined_conformers/3_30_26_top_hits_to_investigate_hbonds/best_hits_review_4_6_26/122 | D7: PV-005890621085 | E7: C([C@@H]1C[C@@H](CCN1C(=O)c1c(C)nco1)C)NC(=O)C1(c2ccccc2)CCC1 | F7: maybe | H7: decent | J7: yes | K7: leaning toward keeping | L7: 3.46182 | M7: none | N7: -16.481134 | O7: 7 | P7: 3 | Q7: 0.285714 | R7: 2 | S7: -1.079586 | T7: 100 | U7: 0 | V7: 0 | W7: 94.724994
A8: cp | B8: ../../all/res122/res122_7F16_receptor_only_PV-006198527401_21_4.pdb | C8: /pi/summer.thyme-umw/rosetta_discovery_space/pth2/shapedb_results/refined_conformers/3_30_26_top_hits_to_investigate_hbonds/best_hits_review_4_6_26/122 | D8: PV-006198527401 | E8: C(CN(C(=O)c1cnccc1C)C)[C@@H](NC(=O)c1c[nH]c(=O)cn1)C(C)(C)C | F8: decent | G8: a lot of questionable interactions seem corroborated by real motifs | H8: decent | J8: yes | K8: isn't perfect, but overall unique and if things rotate could be good | L8: 1.78012 | M8: none | N8: -15.209335 | O8: 9 | P8: 3 | Q8: 0.555556 | R8: 2 | S8: -0.616797 | T8: 100 | U8: 0 | V8: 0 | W8: 98.729424
A9: cp | B9: ../../all/res122/res122_7F16_receptor_only_PV-006630775433_204_2.pdb | C9: /pi/summer.thyme-umw/rosetta_discovery_space/pth2/shapedb_results/refined_conformers/3_30_26_top_hits_to_investigate_hbonds/best_hits_review_4_6_26/122 | D9: PV-006630775433 | E9: N(C[C@@H]1CC(CN1C(=O)CC(C)(C)C)(C)C)C(=O)Cc1nn(C(C)(C)C)nn1 | F9: maybe | H9: decent | J9: yes | K9: leaning toward keeping, kind of stringy but good hbonds | L9: 2.1501 | M9: none | N9: -17.724274 | O9: 8 | P9: 3 | Q9: 0.25 | R9: 2 | S9: -1.29153 | T9: 100 | U9: 0 | V9: 0 | W9: 94.234196
A10: cp | B10: ../../all/res122/res122_7F16_receptor_only_Z1472467618_141_1.pdb | C10: /pi/summer.thyme-umw/rosetta_discovery_space/pth2/shapedb_results/refined_conformers/3_30_26_top_hits_to_investigate_hbonds/best_hits_review_4_6_26/122 | D10: Z1472467618 | E10: N(C(=O)Nc1c(ccc(C)c1)n1cc(C)cn1)Cc1cccc(C(=O)N2CCOCC2)c1 | F10: maybe | H10: decent | J10: yes | L10: 3.28324 | M10: none | N10: -16.448389 | O10: 9 | P10: 3 | Q10: 0.333333 | R10: 2 | S10: -1.562614 | T10: 100 | U10: 0 | V10: 0 | W10: 96.32233
A11: cp | B11: ../../all/res122/res122_7F16_receptor_only_Z373510144_152_4.pdb | C11: /pi/summer.thyme-umw/rosetta_discovery_space/pth2/shapedb_results/refined_conformers/3_30_26_top_hits_to_investigate_hbonds/best_hits_review_4_6_26/122 | D11: Z373510144 | E11: c1(ccccc1NC(=O)c1ccc(OC)cc1)C(=O)N[C@H](C)c1ccc2OCC(=O)Nc2c1 | F11: yes | G11: I don't really see anything bad about this, it is stabilized with multiple hbonds across the pocket | H11: yes | J11: yes | L11: 3.7694 | M11: none | N11: -17.086206 | O11: 7 | P11: 4 | Q11: 0.285714 | R11: 3 | S11: -1.038701 | T11: 100 | U11: 0 | V11: 0 | W11: 96.160807
A12: cp | B12: ../../all/res122/res122_7F16_receptor_only_Z410608138_27_7.pdb | C12: /pi/summer.thyme-umw/rosetta_discovery_space/pth2/shapedb_results/refined_conformers/3_30_26_top_hits_to_investigate_hbonds/best_hits_review_4_6_26/122 | D12: Z410608138 | E12: N(C[C@@H](c1cccc(OC)c1)N1CCCC1)C(=O)Nc1cc(Cl)ccc1N1CCOCC1 | F12: decent | H12: decent | I12: some issues with nitrogen hydrogens, but asn344 could rotate | J12: yes | L12: 4.1438 | M12: none | N12: -15.386234 | O12: 11 | P12: 4 | Q12: 0.454545 | R12: 2 | S12: -0.508212 | T12: 100 | U12: 0 | V12: 0 | W12: 101.5601
A13: cp | B13: ../../all/res269/res269_7F16_receptor_only_PV-000518115177_94_0.pdb | C13: /pi/summer.thyme-umw/rosetta_discovery_space/pth2/shapedb_results/refined_conformers/3_30_26_top_hits_to_investigate_hbonds/best_hits_review_4_6_26/269 | D13: PV-000518115177 | E13: C1N(CCCC[C@H]1NC(=O)c1n(C)c(=O)ccc1)C(=O)CC1(C)CCCCC1 | F13: decent | H13: decent | J13: yes | L13: 2.8567 | M13: none | N13: -15.124595 | O13: 8 | P13: 5 | Q13: 0.375 | R13: 2 | S13: -0.84012 | T13: 100 | U13: 0 | V13: 0 | W13: 99.410285
A14: cp | B14: ../../all/res269/res269_7F16_receptor_only_PV-001699308763_175_2.pdb | C14: /pi/summer.thyme-umw/rosetta_discovery_space/pth2/shapedb_results/refined_conformers/3_30_26_top_hits_to_investigate_hbonds/best_hits_review_4_6_26/269 | D14: PV-001699308763 | E14: [C@@]1(CCCN(C(=O)c2c(cnc(C)n2)Cl)C1)(C)CNC(=O)CN1CCCC1 | F14: decent | H14: decent | J14: yes | L14: 1.89272 | M14: none | N14: -15.196061 | O14: 7 | P14: 2 | Q14: 0.285714 | R14: 2 | S14: -1.471521 | T14: 100 | U14: 0 | V14: 0 | W14: 94.618132
A15: cp | B15: ../../all/res269/res269_7F16_receptor_only_PV-005175010208_60_0.pdb | C15: /pi/summer.thyme-umw/rosetta_discovery_space/pth2/shapedb_results/refined_conformers/3_30_26_top_hits_to_investigate_hbonds/best_hits_review_4_6_26/269 | D15: PV-005175010208 | E15: N1(C(=O)Cc2c(onc2CC)CC)CC[C@@H](O)[C@H](NC(=O)c2cccnc2)C1 | F15: decent | G15: N on 6 member ring could twist to hit TYR122 and be much better | H15: decent | J15: yes | L15: 1.1287 | M15: none | N15: -15.111049 | O15: 8 | P15: 4 | Q15: 0.5 | R15: 3 | S15: -1.488021 | T15: 100 | U15: 0 | V15: 0 | W15: 98.90093
A16: cp | B16: ../../all/res269/res269_7F16_receptor_only_PV-006596664813_71_2.pdb | C16: /pi/summer.thyme-umw/rosetta_discovery_space/pth2/shapedb_results/refined_conformers/3_30_26_top_hits_to_investigate_hbonds/best_hits_review_4_6_26/269 | D16: PV-006596664813 | E16: C1(C[C@H](C)NC(=O)c2cn(C)nn2)CN(C(=O)c2c3CC(C)(C)Cc3ccc2)C1 | F16: maybe | H16: decent | J16: yes | L16: 2.2205 | M16: none | N16: -15.19198 | O16: 8 | P16: 3 | Q16: 0.375 | R16: 2 | S16: -1.182302 | T16: 100 | U16: 0 | V16: 0 | W16: 97.000718
A17: cp | B17: ../../all/res269/res269_7F16_receptor_only_PV-006598988224_102_4.pdb | C17: /pi/summer.thyme-umw/rosetta_discovery_space/pth2/shapedb_results/refined_conformers/3_30_26_top_hits_to_investigate_hbonds/best_hits_review_4_6_26/269 | D17: PV-006598988224 | E17: [C@@H]1(NC(=O)CC2CCCC2)CCN(C(=O)c2cc(=O)[nH]nc2)[C@H]1c1ccccc1 | F17: maybe | H17: yes | J17: yes | L17: 2.4222 | M17: none | N17: -15.653385 | O17: 8 | P17: 3 | Q17: 0.25 | R17: 2 | S17: -0.166637 | T17: 100 | U17: 0 | V17: 0 | W17: 97.429978
A18: cp | B18: ../../all/res269/res269_7F16_receptor_only_PV-006712468448_190_0.pdb | C18: /pi/summer.thyme-umw/rosetta_discovery_space/pth2/shapedb_results/refined_conformers/3_30_26_top_hits_to_investigate_hbonds/best_hits_review_4_6_26/269 | D18: PV-006712468448 | E18: C(=O)(N1C[C@H](NC(=O)C(C)C)[C@@H](C1)C)Cc1ccccc1Oc1ccncc1 | F18: maybe | G18: same pose as PV-006712468449, enantiomer | H18: decent | J18: yes | L18: 3.0355 | M18: none | N18: -15.759066 | O18: 7 | P18: 2 | Q18: 0.571429 | R18: 2 | S18: -0.931789 | T18: 100 | U18: 0 | V18: 0 | W18: 94.880574

Sheet res122 filter best placements
B1: file | D1: ligand_name | E1: Does Ari Like? | F1: Comments | G1: Does Summer Like? | H1: Comments | I1: Final Thoughts/Selection? | J1: Comments | K1: smiles | L1: cLogp | M1: anchor | N1: ddg | O1: total_motifs | P1: significant_motifs | Q1: real_motif_ratio | R1: hbond_motif_count | S1: hbond_motif_energy_sum | T1: closest_autodock_recovery_rmsd | U1: closest_autodock_recovery_ddg | V1: strain_energy | W1: total
A2: cp | B2: ../../all/res122/res122_7F16_receptor_only_PV-003476110573_20_3.pdb | C2: /pi/summer.thyme-umw/rosetta_discovery_space/pth2/shapedb_results/refined_conformers/3_30_26_top_hits_to_investigate_hbonds/best_hits_review_4_6_26/122 | D2: PV-003476110573 | E2: ='res122 Ari'!C2 -> maybe | F2: ='res122 Ari'!D2 -> probably reject over how it hits arg160 and asn402 | G2: ='res122 Summer'!C2 -> yes | H2: ='res122 Summer'!D2 | I2: yes | J2: lean toward keeping | K2: c1(n(nc([C@H](CCC)C)n1)C1CC1)c1ccc2ncn(C)c(=O)c2c1 | L2: 3.4305 | M2: =IFERROR(__xludf.DUMMYFUNCTION("IFERROR(REGEXEXTRACT(G2, ""res(269|122)""), ""none"")"),"none") -> none | N2: -15.535781 | O2: 9 | P2: 3 | Q2: 0.444444 | R2: 2 | S2: -1.719191 | T2: 100 | U2: 0 | V2: 0 | W2: 97.189472
A3: cp | B3: ../../all/res122/res122_7F16_receptor_only_PV-004506477178_31_0.pdb | C3: /pi/summer.thyme-umw/rosetta_discovery_space/pth2/shapedb_results/refined_conformers/3_30_26_top_hits_to_investigate_hbonds/best_hits_review_4_6_26/122 | D3: PV-004506477178 | E3: ='res122 Ari'!C7 -> decent | F3: ='res122 Ari'!D7 -> it's bendy, but I like how it hits overall. check strain score | G3: ='res122 Summer'!C7 -> decent | H3: ='res122 Summer'!D7 | I3: no | J3: will it even form this bendy thing? | K3: C(CCN(C(=O)c1nccc(C)n1)C)N(C)C(=O)c1ccc2CCC(=O)Nc2c1 | L3: 1.90402 | M3: =IFERROR(__xludf.DUMMYFUNCTION("IFERROR(REGEXEXTRACT(G3, ""res(269|122)""), ""none"")"),"none") -> none | N3: -16.222639 | O3: 10 | P3: 3 | Q3: 0.3 | R3: 2 | S3: -1.763647 | T3: 100 | U3: 0 | V3: 0 | W3: 97.313714
A4: cp | B4: ../../all/res122/res122_7F16_receptor_only_PV-004506718703_31_1.pdb | C4: /pi/summer.thyme-umw/rosetta_discovery_space/pth2/shapedb_results/refined_conformers/3_30_26_top_hits_to_investigate_hbonds/best_hits_review_4_6_26/122 | D4: PV-004506718703 | E4: ='res122 Ari'!C8 -> maybe | F4: ='res122 Ari'!D8 -> misses res122 but pose looks not terrible | G4: ='res122 Summer'!C8 -> decent | H4: ='res122 Summer'!D8 | I4: yes | J4: lean toward keeping | K4: [C@H]1(NC(=O)Cc2nonc2C)CN(C(=O)c2c(C)n(C)c3ccccc23)C[C@H]1C | L4: 1.99754 | M4: =IFERROR(__xludf.DUMMYFUNCTION("IFERROR(REGEXEXTRACT(G4, ""res(269|122)""), ""none"")"),"none") -> none | N4: -15.296063 | O4: 8 | P4: 3 | Q4: 0.25 | R4: 2 | S4: -1.293353 | T4: 100 | U4: 0 | V4: 0 | W4: 96.660584
A5: cp | B5: ../../all/res122/res122_7F16_receptor_only_PV-004655902680_26_5.pdb | C5: /pi/summer.thyme-umw/rosetta_discovery_space/pth2/shapedb_results/refined_conformers/3_30_26_top_hits_to_investigate_hbonds/best_hits_review_4_6_26/122 | D5: PV-004655902680 | E5: ='res122 Ari'!C10 -> decent | F5: ='res122 Ari'!D10 -> can carbonyl point into tyrosine like into a benzene? | G5: ='res122 Summer'!C10 -> yes | H5: ='res122 Summer'!D10 | I5: yes | J5: risky, but lean towards keeping | K5: C1[C@@H](N(CCCN1C(=O)c1c(cc(C)[nH]1)C)C(=O)[C@@H]1CCOC1)c1ccccc1 | L5: 3.08384 | M5: =IFERROR(__xludf.DUMMYFUNCTION("IFERROR(REGEXEXTRACT(G5, ""res(269|122)""), ""none"")"),"none") -> none | N5: -15.950047 | O5: 7 | P5: 3 | Q5: 0.285714 | R5: 3 | S5: -1.505897 | T5: 100 | U5: 0 | V5: 0 | W5: 95.82977
A6: cp | B6: ../../all/res122/res122_7F16_receptor_only_PV-004887538871_10_3.pdb | C6: /pi/summer.thyme-umw/rosetta_discovery_space/pth2/shapedb_results/refined_conformers/3_30_26_top_hits_to_investigate_hbonds/best_hits_review_4_6_26/122 | D6: PV-004887538871 | E6: ='res122 Ari'!C12 -> maybe | F6: ='res122 Ari'!D12 -> not great against tyr122 | G6: ='res122 Summer'!C12 -> decent | H6: ='res122 Summer'!D12 | I6: maybe | J6: will tyr122 be ok? skipping | K6: [C@H]1(CN(C(=O)c2c(cccc2C)F)C)COCCN1C(=O)CC1CN(C)C1 | L6: 1.38522 | M6: =IFERROR(__xludf.DUMMYFUNCTION("IFERROR(REGEXEXTRACT(G6, ""res(269|122)""), ""none"")"),"none") -> none | N6: -15.476613 | O6: 12 | P6: 4 | Q6: 0.333333 | R6: 2 | S6: -0.623346 | T6: 100 | U6: 0 | V6: 0 | W6: 102.23337
A7: cp | B7: ../../all/res122/res122_7F16_receptor_only_PV-005424082445_136_0.pdb | C7: /pi/summer.thyme-umw/rosetta_discovery_space/pth2/shapedb_results/refined_conformers/3_30_26_top_hits_to_investigate_hbonds/best_hits_review_4_6_26/122 | D7: PV-005424082445 | E7: ='res122 Ari'!C17 -> maybe | F7: ='res122 Ari'!D17 | G7: ='res122 Summer'!C17 -> decent | H7: ='res122 Summer'!D17 | I7: yes | J7: isn't amazing, but diverse placement | K7: [C@@H]1(CCN(C(=O)Cc2cnccc2OC)[C@@H]1C)NC(=O)Cc1cc(C)cc(C)c1 | L7: 2.59784 | M7: =IFERROR(__xludf.DUMMYFUNCTION("IFERROR(REGEXEXTRACT(G7, ""res(269|122)""), ""none"")"),"none") -> none | N7: -15.040718 | O7: 6 | P7: 3 | Q7: 0.333333 | R7: 2 | S7: -1.138986 | T7: 100 | U7: 0 | V7: 0 | W7: 95.153629
A8: cp | B8: ../../all/res122/res122_7F16_receptor_only_PV-005510814641_23_0.pdb | C8: /pi/summer.thyme-umw/rosetta_discovery_space/pth2/shapedb_results/refined_conformers/3_30_26_top_hits_to_investigate_hbonds/best_hits_review_4_6_26/122 | D8: PV-005510814641 | E8: ='res122 Ari'!C18 -> decent | F8: ='res122 Ari'!D18 -> I like all the intereactions and maybe tyr188 could work | G8: ='res122 Summer'!C18 -> yes | H8: ='res122 Summer'!D18 | I8: yes | J8: little floppy, but lots of good interactions | K8: C1N(CCCC[C@H]1N(C(=O)c1c(c(C)[nH]n1)F)C)C(=O)CCS(=O)(=O)C | L8: 0.74502 | M8: =IFERROR(__xludf.DUMMYFUNCTION("IFERROR(REGEXEXTRACT(G8, ""res(269|122)""), ""none"")"),"none") -> none | N8: -15.260381 | O8: 8 | P8: 3 | Q8: 0.25 | R8: 3 | S8: -1.428861 | T8: 100 | U8: 0 | V8: 0 | W8: 97.560758
A9: cp | B9: ../../all/res122/res122_7F16_receptor_only_PV-005890621085_19_0.pdb | C9: /pi/summer.thyme-umw/rosetta_discovery_space/pth2/shapedb_results/refined_conformers/3_30_26_top_hits_to_investigate_hbonds/best_hits_review_4_6_26/122 | D9: PV-005890621085 | E9: ='res122 Ari'!C23 -> maybe | F9: ='res122 Ari'!D23 | G9: ='res122 Summer'!C23 -> decent | H9: ='res122 Summer'!D23 | I9: yes | J9: leaning toward keeping | K9: C([C@@H]1C[C@@H](CCN1C(=O)c1c(C)nco1)C)NC(=O)C1(c2ccccc2)CCC1 | L9: 3.46182 | M9: =IFERROR(__xludf.DUMMYFUNCTION("IFERROR(REGEXEXTRACT(G9, ""res(269|122)""), ""none"")"),"none") -> none | N9: -16.481134 | O9: 7 | P9: 3 | Q9: 0.285714 | R9: 2 | S9: -1.079586 | T9: 100 | U9: 0 | V9: 0 | W9: 94.724994
A10: cp | B10: ../../all/res122/res122_7F16_receptor_only_PV-006198527401_21_4.pdb | C10: /pi/summer.thyme-umw/rosetta_discovery_space/pth2/shapedb_results/refined_conformers/3_30_26_top_hits_to_investigate_hbonds/best_hits_review_4_6_26/122 | D10: PV-006198527401 | E10: ='res122 Ari'!C24 -> decent | F10: ='res122 Ari'!D24 -> a lot of questionable interactions seem corroborated by real motifs | G10: ='res122 Summer'!C24 -> decent | H10: ='res122 Summer'!D24 | I10: yes | J10: isn't perfect, but overall unique and if things rotate could be good | K10: C(CN(C(=O)c1cnccc1C)C)[C@@H](NC(=O)c1c[nH]c(=O)cn1)C(C)(C)C | L10: 1.78012 | M10: =IFERROR(__xludf.DUMMYFUNCTION("IFERROR(REGEXEXTRACT(G10, ""res(269|122)""), ""none"")"),"none") -> none | N10: -15.209335 | O10: 9 | P10: 3 | Q10: 0.555556 | R10: 2 | S10: -0.616797 | T10: 100 | U10: 0 | V10: 0 | W10: 98.729424
A11: cp | B11: ../../all/res122/res122_7F16_receptor_only_PV-006630775433_204_2.pdb | C11: /pi/summer.thyme-umw/rosetta_discovery_space/pth2/shapedb_results/refined_conformers/3_30_26_top_hits_to_investigate_hbonds/best_hits_review_4_6_26/122 | D11: PV-006630775433 | E11: ='res122 Ari'!C27 -> maybe | F11: ='res122 Ari'!D27 | G11: ='res122 Summer'!C27 -> decent | H11: ='res122 Summer'!D27 | I11: yes | J11: leaning toward keeping, kind of stringy but good hbonds | K11: N(C[C@@H]1CC(CN1C(=O)CC(C)(C)C)(C)C)C(=O)Cc1nn(C(C)(C)C)nn1 | L11: 2.1501 | M11: =IFERROR(__xludf.DUMMYFUNCTION("IFERROR(REGEXEXTRACT(G11, ""res(269|122)""), ""none"")"),"none") -> none | N11: -17.724274 | O11: 8 | P11: 3 | Q11: 0.25 | R11: 2 | S11: -1.29153 | T11: 100 | U11: 0 | V11: 0 | W11: 94.234196
A12: cp | B12: ../../all/res122/res122_7F16_receptor_only_Z1472467618_141_1.pdb | C12: /pi/summer.thyme-umw/rosetta_discovery_space/pth2/shapedb_results/refined_conformers/3_30_26_top_hits_to_investigate_hbonds/best_hits_review_4_6_26/122 | D12: Z1472467618 | E12: ='res122 Ari'!C29 -> maybe | F12: ='res122 Ari'!D29 | G12: ='res122 Summer'!C29 -> decent | H12: ='res122 Summer'!D29 | I12: yes | J12: ='res122 Mary Shay'!D29 | K12: N(C(=O)Nc1c(ccc(C)c1)n1cc(C)cn1)Cc1cccc(C(=O)N2CCOCC2)c1 | L12: 3.28324 | M12: =IFERROR(__xludf.DUMMYFUNCTION("IFERROR(REGEXEXTRACT(G12, ""res(269|122)""), ""none"")"),"none") -> none | N12: -16.448389 | O12: 9 | P12: 3 | Q12: 0.333333 | R12: 2 | S12: -1.562614 | T12: 100 | U12: 0 | V12: 0 | W12: 96.32233
A13: cp | B13: ../../all/res122/res122_7F16_receptor_only_Z1521810617_4_7.pdb | C13: /pi/summer.thyme-umw/rosetta_discovery_space/pth2/shapedb_results/refined_conformers/3_30_26_top_hits_to_investigate_hbonds/best_hits_review_4_6_26/122 | D13: Z1521810617 | E13: ='res122 Ari'!C30 -> maybe | F13: ='res122 Ari'!D30 | G13: ='res122 Summer'!C30 -> decent | H13: ='res122 Summer'!D30 | I13: maybe | J13: leaning toward skipping | K13: N([C@H](C(=O)N1C[C@H](C)O[C@@H](C1)C)c1ccccc1)C(=O)c1cncc(N2CCOCC2)c1 | L13: 2.0251 | M13: =IFERROR(__xludf.DUMMYFUNCTION("IFERROR(REGEXEXTRACT(G13, ""res(269|122)""), ""none"")"),"none") -> none | N13: -16.810235 | O13: 9 | P13: 3 | Q13: 0.444444 | R13: 2 | S13: -0.880047 | T13: 100 | U13: 0 | V13: 0 | W13: 96.754162
A14: cp | B14: ../../all/res122/res122_7F16_receptor_only_Z1712441482_38_2.pdb | C14: /pi/summer.thyme-umw/rosetta_discovery_space/pth2/shapedb_results/refined_conformers/3_30_26_top_hits_to_investigate_hbonds/best_hits_review_4_6_26/122 | D14: Z1712441482 | E14: ='res122 Ari'!C32 -> maybe | F14: ='res122 Ari'!D32 | G14: ='res122 Summer'!C32 -> decent | H14: ='res122 Summer'!D32 | I14: no | J14: ='res122 Mary Shay'!D32 | K14: C(=O)([C@H](C)NC1=NS(=O)(=O)c2ccccc12)N[C@H](C)C(c1ccccc1)c1ccccc1 | L14: 3.4504 | M14: =IFERROR(__xludf.DUMMYFUNCTION("IFERROR(REGEXEXTRACT(G14, ""res(269|122)""), ""none"")"),"none") -> none | N14: -15.035637 | O14: 8 | P14: 4 | Q14: 0.25 | R14: 2 | S14: -0.915905 | T14: 100 | U14: 0 | V14: 0 | W14: 98.298458
A15: cp | B15: ../../all/res122/res122_7F16_receptor_only_Z3011172425_6_0.pdb | C15: /pi/summer.thyme-umw/rosetta_discovery_space/pth2/shapedb_results/refined_conformers/3_30_26_top_hits_to_investigate_hbonds/best_hits_review_4_6_26/122 | D15: Z3011172425 | E15: ='res122 Ari'!C38 -> maybe | F15: ='res122 Ari'!D38 | G15: ='res122 Summer'!C38 -> decent | H15: ='res122 Summer'!D38 | I15: maybe | J15: skip | K15: N([C@@H]1CC[C@@H](CC)CC1)(C)c1nnc(c2cccnn2)n1C[C@@H]1CCOC1 | L15: 3.1766 | M15: =IFERROR(__xludf.DUMMYFUNCTION("IFERROR(REGEXEXTRACT(G15, ""res(269|122)""), ""none"")"),"none") -> none | N15: -17.375967 | O15: 8 | P15: 3 | Q15: 0.25 | R15: 2 | S15: -1.320226 | T15: 100 | U15: 0 | V15: 0 | W15: 94.553807
A16: cp | B16: ../../all/res122/res122_7F16_receptor_only_Z373510144_152_4.pdb | C16: /pi/summer.thyme-umw/rosetta_discovery_space/pth2/shapedb_results/refined_conformers/3_30_26_top_hits_to_investigate_hbonds/best_hits_review_4_6_26/122 | D16: Z373510144 | E16: ='res122 Ari'!C40 -> yes | F16: ='res122 Ari'!D40 -> I don't really see anything bad about this, it is stabilized with multiple hbonds across the pocket | G16: ='res122 Summer'!C40 -> yes | H16: ='res122 Summer'!D40 | I16: yes | J16: ='res122 Mary Shay'!D40 | K16: c1(ccccc1NC(=O)c1ccc(OC)cc1)C(=O)N[C@H](C)c1ccc2OCC(=O)Nc2c1 | L16: 3.7694 | M16: =IFERROR(__xludf.DUMMYFUNCTION("IFERROR(REGEXEXTRACT(G16, ""res(269|122)""), ""none"")"),"none") -> none | N16: -17.086206 | O16: 7 | P16: 4 | Q16: 0.285714 | R16: 3 | S16: -1.038701 | T16: 100 | U16: 0 | V16: 0 | W16: 96.160807
A17: cp | B17: ../../all/res122/res122_7F16_receptor_only_Z410608138_27_7.pdb | C17: /pi/summer.thyme-umw/rosetta_discovery_space/pth2/shapedb_results/refined_conformers/3_30_26_top_hits_to_investigate_hbonds/best_hits_review_4_6_26/122 | D17: Z410608138 | E17: ='res122 Ari'!C41 -> decent | F17: ='res122 Ari'!D41 | G17: ='res122 Summer'!C41 -> decent | H17: ='res122 Summer'!D41 -> some issues with nitrogen hydrogens, but asn344 could rotate | I17: yes | J17: ='res122 Mary Shay'!D41 | K17: N(C[C@@H](c1cccc(OC)c1)N1CCCC1)C(=O)Nc1cc(Cl)ccc1N1CCOCC1 | L17: 4.1438 | M17: =IFERROR(__xludf.DUMMYFUNCTION("IFERROR(REGEXEXTRACT(G17, ""res(269|122)""), ""none"")"),"none") -> none | N17: -15.386234 | O17: 11 | P17: 4 | Q17: 0.454545 | R17: 2 | S17: -0.508212 | T17: 100 | U17: 0 | V17: 0 | W17: 101.5601
A18: cp | B18: ../../all/res122/res122_7F16_receptor_only_Z4403343830_181_8.pdb | C18: /pi/summer.thyme-umw/rosetta_discovery_space/pth2/shapedb_results/refined_conformers/3_30_26_top_hits_to_investigate_hbonds/best_hits_review_4_6_26/122 | D18: Z4403343830 | E18: ='res122 Ari'!C42 -> decent | F18: ='res122 Ari'!D42 | G18: ='res122 Summer'!C42 -> maybe | H18: ='res122 Summer'!D42 | I18: maybe | J18: skip | K18: N1(CCC[C@@H]([C@@H](C)CC(=O)O)C1)C(=O)c1ccc(Cl)c(N2CCCC2=O)c1 | L18: 3.4298 | M18: =IFERROR(__xludf.DUMMYFUNCTION("IFERROR(REGEXEXTRACT(G18, ""res(269|122)""), ""none"")"),"none") -> none | N18: -16.231911 | O18: 12 | P18: 2 | Q18: 0.25 | R18: 2 | S18: -0.38947 | T18: 100 | U18: 0 | V18: 0 | W18: 99.628619
I19: ='res122 Mary Shay'!C45 | J19: ='res122 Mary Shay'!D45
I20: ='res122 Mary Shay'!C46 | J20: ='res122 Mary Shay'!D46
I21: ='res122 Mary Shay'!C47 | J21: ='res122 Mary Shay'!D47
I22: ='res122 Mary Shay'!C48 | J22: ='res122 Mary Shay'!D48
I23: ='res122 Mary Shay'!C49 | J23: ='res122 Mary Shay'!D49
I24: ='res122 Mary Shay'!C50 | J24: ='res122 Mary Shay'!D50
I25: ='res122 Mary Shay'!C51 | J25: ='res122 Mary Shay'!D51
I26: ='res122 Mary Shay'!C52 | J26: ='res122 Mary Shay'!D52
I27: ='res122 Mary Shay'!C53 | J27: ='res122 Mary Shay'!D53
I28: ='res122 Mary Shay'!C54 | J28: ='res122 Mary Shay'!D54
I29: ='res122 Mary Shay'!C55 | J29: ='res122 Mary Shay'!D55
I30: ='res122 Mary Shay'!C56 | J30: ='res122 Mary Shay'!D56
... I103: ='res122 Mary Shay'!C129 | J103: ='res122 Mary Shay'!D129

Sheet res269 filter best placements
B1: file | D1: ligand_name | E1: Does Ari Like? | F1: Comments | G1: Does Summer Like? | H1: Comments | I1: Final Thoughts/Selection? | J1: Comments | K1: smiles | L1: cLogp | M1: anchor | N1: ddg | O1: total_motifs | P1: significant_motifs | Q1: real_motif_ratio | R1: hbond_motif_count | S1: hbond_motif_energy_sum | T1: closest_autodock_recovery_rmsd | U1: closest_autodock_recovery_ddg | V1: strain_energy | W1: total
A2: cp | B2: ../../all/res269/res269_7F16_receptor_only_PV-000366782609_149_11.pdb | C2: /pi/summer.thyme-umw/rosetta_discovery_space/pth2/shapedb_results/refined_conformers/3_30_26_top_hits_to_investigate_hbonds/best_hits_review_4_6_26/269 | D2: PV-000366782609 | E2: ='res269 Ari'!C2 -> maybe | F2: ='res269 Ari'!D2 | G2: ='res269 Summer'!C2 -> decent | H2: ='res269 Summer'!D2 | I2: maybe | J2: ='res269 Mary Shay'!D2 | K2: O(C1CN(C(=O)C(C)(C)N2CCCCC2)C1)C1CCN(C(=O)CC2CC2)CC1 | L2: 2.2694 | M2: =IFERROR(__xludf.DUMMYFUNCTION("IFERROR(REGEXEXTRACT(G2, ""res(269|122)""), ""none"")"),"none") -> none | N2: -16.620105 | O2: 12 | P2: 3 | Q2: 0.416667 | R2: 2 | S2: -0.664324 | T2: 100 | U2: 0 | V2: 0 | W2: 100.13224
A3: cp | B3: ../../all/res269/res269_7F16_receptor_only_PV-000518115177_94_0.pdb | C3: /pi/summer.thyme-umw/rosetta_discovery_space/pth2/shapedb_results/refined_conformers/3_30_26_top_hits_to_investigate_hbonds/best_hits_review_4_6_26/269 | D3: PV-000518115177 | E3: ='res269 Ari'!C5 -> decent | F3: ='res269 Ari'!D5 | G3: ='res269 Summer'!C5 -> decent | H3: ='res269 Summer'!D5 | I3: yes | J3: ='res269 Mary Shay'!D5 | K3: C1N(CCCC[C@H]1NC(=O)c1n(C)c(=O)ccc1)C(=O)CC1(C)CCCCC1 | L3: 2.8567 | M3: =IFERROR(__xludf.DUMMYFUNCTION("IFERROR(REGEXEXTRACT(G3, ""res(269|122)""), ""none"")"),"none") -> none | N3: -15.124595 | O3: 8 | P3: 5 | Q3: 0.375 | R3: 2 | S3: -0.84012 | T3: 100 | U3: 0 | V3: 0 | W3: 99.410285
A4: cp | B4: ../../all/res269/res269_7F16_receptor_only_PV-001577237854_122_9.pdb | C4: /pi/summer.thyme-umw/rosetta_discovery_space/pth2/shapedb_results/refined_conformers/3_30_26_top_hits_to_investigate_hbonds/best_hits_review_4_6_26/269 | D4: PV-001577237854 | E4: ='res269 Ari'!C7 -> maybe | F4: ='res269 Ari'!D7 | G4: ='res269 Summer'!C7 -> decent | H4: ='res269 Summer'!D7 | I4: no | J4: ='res269 Mary Shay'!D7 | K4: C1N(CCC[C@H]1[C@H](NC(=O)CC(C)C)C)C(=O)c1ccccc1n1cccc1 | L4: 3.8803 | M4: =IFERROR(__xludf.DUMMYFUNCTION("IFERROR(REGEXEXTRACT(G4, ""res(269|122)""), ""none"")"),"none") -> none | N4: -15.234041 | O4: 8 | P4: 3 | Q4: 0.25 | R4: 3 | S4: -0.552818 | T4: 100 | U4: 0 | V4: 0 | W4: 98.463141
A5: cp | B5: ../../all/res269/res269_7F16_receptor_only_PV-001699308763_175_2.pdb | C5: /pi/summer.thyme-umw/rosetta_discovery_space/pth2/shapedb_results/refined_conformers/3_30_26_top_hits_to_investigate_hbonds/best_hits_review_4_6_26/269 | D5: PV-001699308763 | E5: ='res269 Ari'!C8 -> decent | F5: ='res269 Ari'!D8 | G5: ='res269 Summer'!C8 -> decent | H5: ='res269 Summer'!D8 | I5: yes | J5: ='res269 Mary Shay'!D8 | K5: [C@@]1(CCCN(C(=O)c2c(cnc(C)n2)Cl)C1)(C)CNC(=O)CN1CCCC1 | L5: 1.89272 | M5: =IFERROR(__xludf.DUMMYFUNCTION("IFERROR(REGEXEXTRACT(G5, ""res(269|122)""), ""none"")"),"none") -> none | N5: -15.196061 | O5: 7 | P5: 2 | Q5: 0.285714 | R5: 2 | S5: -1.471521 | T5: 100 | U5: 0 | V5: 0 | W5: 94.618132
A6: cp | B6: ../../all/res269/res269_7F16_receptor_only_PV-004563691650_194_8.pdb | C6: /pi/summer.thyme-umw/rosetta_discovery_space/pth2/shapedb_results/refined_conformers/3_30_26_top_hits_to_investigate_hbonds/best_hits_review_4_6_26/269 | D6: PV-004563691650 | E6: ='res269 Ari'!C15 -> decent | F6: ='res269 Ari'!D15 | G6: ='res269 Summer'!C15 -> no | H6: ='res269 Summer'!D15 | I6: no | J6: ='res269 Mary Shay'!D15 | K6: C([C@H](N(C(=O)c1ccccc1C)C)C1CC1)NC(=O)c1nn2CCCC(=O)c2c1 | L6: 2.44862 | M6: =IFERROR(__xludf.DUMMYFUNCTION("IFERROR(REGEXEXTRACT(G6, ""res(269|122)""), ""none"")"),"none") -> none | N6: -15.778424 | O6: 10 | P6: 4 | Q6: 0.3 | R6: 2 | S6: -0.444144 | T6: 100 | U6: 0 | V6: 0 | W6: 100.07743
A7: cp | B7: ../../all/res269/res269_7F16_receptor_only_PV-004702335537_21_10.pdb | C7: /pi/summer.thyme-umw/rosetta_discovery_space/pth2/shapedb_results/refined_conformers/3_30_26_top_hits_to_investigate_hbonds/best_hits_review_4_6_26/269 | D7: PV-004702335537 | E7: ='res269 Ari'!C16 -> maybe | F7: ='res269 Ari'!D16 | G7: ='res269 Summer'!C16 -> decent | H7: ='res269 Summer'!D16 | I7: maybe | J7: ='res269 Mary Shay'!D16 | K7: C1[C@@H](C[C@H](OC)CN1C(=O)[C@H]1CCCN1C(C)C)NC(=O)[C@@H](O)C1CCC1 | L7: 0.7523 | M7: =IFERROR(__xludf.DUMMYFUNCTION("IFERROR(REGEXEXTRACT(G7, ""res(269|122)""), ""none"")"),"none") -> none | N7: -16.377062 | O7: 9 | P7: 1 | Q7: 0.333333 | R7: 2 | S7: -1.84415 | T7: 100 | U7: 0 | V7: 0 | W7: 94.112121
A8: cp | B8: ../../all/res269/res269_7F16_receptor_only_PV-004860315998_45_2.pdb | C8: /pi/summer.thyme-umw/rosetta_discovery_space/pth2/shapedb_results/refined_conformers/3_30_26_top_hits_to_investigate_hbonds/best_hits_review_4_6_26/269 | D8: PV-004860315998 | E8: ='res269 Ari'!C18 -> decent | F8: ='res269 Ari'!D18 | G8: ='res269 Summer'!C18 -> no | H8: ='res269 Summer'!D18 | I8: no | J8: ='res269 Mary Shay'!D18 | K8: C(CNC(=O)CN1CCCCC1)[C@@H]1CCN(C(=O)[C@@H]2CCCC3(CCC3)O2)C1 | L8: 2.3189 | M8: =IFERROR(__xludf.DUMMYFUNCTION("IFERROR(REGEXEXTRACT(G8, ""res(269|122)""), ""none"")"),"none") -> none | N8: -16.004339 | O8: 7 | P8: 1 | Q8: 0.285714 | R8: 2 | S8: -0.643672 | T8: 100 | U8: 0 | V8: 0 | W8: 93.637703
A9: cp | B9: ../../all/res269/res269_7F16_receptor_only_PV-005175010208_60_0.pdb | C9: /pi/summer.thyme-umw/rosetta_discovery_space/pth2/shapedb_results/refined_conformers/3_30_26_top_hits_to_investigate_hbonds/best_hits_review_4_6_26/269 | D9: PV-005175010208 | E9: ='res269 Ari'!C21 -> decent | F9: ='res269 Ari'!D21 -> N on 6 member ring could twist to hit TYR122 and be much better | G9: ='res269 Summer'!C21 -> decent | H9: ='res269 Summer'!D21 | I9: yes | J9: ='res269 Mary Shay'!D21 | K9: N1(C(=O)Cc2c(onc2CC)CC)CC[C@@H](O)[C@H](NC(=O)c2cccnc2)C1 | L9: 1.1287 | M9: =IFERROR(__xludf.DUMMYFUNCTION("IFERROR(REGEXEXTRACT(G9, ""res(269|122)""), ""none"")"),"none") -> none | N9: -15.111049 | O9: 8 | P9: 4 | Q9: 0.5 | R9: 3 | S9: -1.488021 | T9: 100 | U9: 0 | V9: 0 | W9: 98.90093
A10: cp | B10: ../../all/res269/res269_7F16_receptor_only_PV-005397290947_10_1.pdb | C10: /pi/summer.thyme-umw/rosetta_discovery_space/pth2/shapedb_results/refined_conformers/3_30_26_top_hits_to_investigate_hbonds/best_hits_review_4_6_26/269 | D10: PV-005397290947 | E10: ='res269 Ari'!C25 -> yes | F10: ='res269 Ari'!D25 -> it sits high, but I like all of its interactions | G10: ='res269 Summer'!C25 -> no | H10: ='res269 Summer'!D25 | I10: no | J10: ='res269 Mary Shay'!D25 | K10: C(=O)([C@@H]1CC[C@@H](NC(=O)C)CC1)N1C[C@@H]2CC[C@H](C1)N2C(=O)c1csnc1 | L10: 1.6534 | M10: =IFERROR(__xludf.DUMMYFUNCTION("IFERROR(REGEXEXTRACT(G10, ""res(269|122)""), ""none"")"),"none") -> none | N10: -15.787491 | O10: 6 | P10: 2 | Q10: 0.333333 | R10: 3 | S10: -1.153959 | T10: 100 | U10: 0 | V10: 0 | W10: 94.391883
A11: cp | B11: ../../all/res269/res269_7F16_receptor_only_PV-005409743762_202_0.pdb | C11: /pi/summer.thyme-umw/rosetta_discovery_space/pth2/shapedb_results/refined_conformers/3_30_26_top_hits_to_investigate_hbonds/best_hits_review_4_6_26/269 | D11: PV-005409743762 | E11: ='res269 Ari'!C26 -> decent | F11: ='res269 Ari'!D26 | G11: ='res269 Summer'!C26 -> no | H11: ='res269 Summer'!D26 | I11: no | J11: ='res269 Mary Shay'!D26 | K11: C(NC(=O)Cc1onc(C)c1)[C@]1(C)CN(C(=O)[C@@H]2CCCCC2(C)C)CCO1 | L11: 2.47562 | M11: =IFERROR(__xludf.DUMMYFUNCTION("IFERROR(REGEXEXTRACT(G11, ""res(269|122)""), ""none"")"),"none") -> none | N11: -16.526444 | O11: 7 | P11: 3 | Q11: 0.428571 | R11: 3 | S11: -1.370961 | T11: 100 | U11: 0 | V11: 0 | W11: 95.531166
A12: cp | B12: ../../all/res269/res269_7F16_receptor_only_PV-005460257111_135_1.pdb | C12: /pi/summer.thyme-umw/rosetta_discovery_space/pth2/shapedb_results/refined_conformers/3_30_26_top_hits_to_investigate_hbonds/best_hits_review_4_6_26/269 | D12: PV-005460257111 | E12: ='res269 Ari'!C27 -> yes | F12: ='res269 Ari'!D27 -> lots of good interactions and extends across the pocket, even if there are a lot of interactions not considered real; enantiomer with PV-005460257111 | G12: ='res269 Summer'!C27 -> no | H12: ='res269 Summer'!D27 | I12: no | J12: ='res269 Mary Shay'!D27 | K12: [C@@H](CNC(=O)[C@H]1N=C(C)Nc2[nH]ccc12)(C)CNC(=O)[C@@]12CCC[C@@H]1CCC2 | L12: 2.7386 | M12: =IFERROR(__xludf.DUMMYFUNCTION("IFERROR(REGEXEXTRACT(G12, ""res(269|122)""), ""none"")"),"none") -> none | N12: -15.442965 | O12: 7 | P12: 3 | Q12: 0.285714 | R12: 2 | S12: -0.995888 | T12: 100 | U12: 0 | V12: 0 | W12: 95.846861
A13: cp | B13: ../../all/res269/res269_7F16_receptor_only_PV-005771589697_43_4.pdb | C13: /pi/summer.thyme-umw/rosetta_discovery_space/pth2/shapedb_results/refined_conformers/3_30_26_top_hits_to_investigate_hbonds/best_hits_review_4_6_26/269 | D13: PV-005771589697 | E13: ='res269 Ari'!C33 -> decent | F13: ='res269 Ari'!D33 -> could hit glu398 better | G13: ='res269 Summer'!C33 -> no | H13: ='res269 Summer'!D33 | I13: no | J13: ='res269 Mary Shay'!D33 | K13: N(C(=O)CSc1ccc(C)cc1)[C@@H]1[C@H]2CCN(C(=O)c3c(C)cnc(C)c3)[C@@H]12 | L13: 3.12826 | M13: =IFERROR(__xludf.DUMMYFUNCTION("IFERROR(REGEXEXTRACT(G13, ""res(269|122)""), ""none"")"),"none") -> none | N13: -15.155078 | O13: 8 | P13: 2 | Q13: 0.25 | R13: 2 | S13: -0.394031 | T13: 100 | U13: 0 | V13: 0 | W13: 96.700891
A14: cp | B14: ../../all/res269/res269_7F16_receptor_only_PV-005792794357_162_6.pdb | C14: /pi/summer.thyme-umw/rosetta_discovery_space/pth2/shapedb_results/refined_conformers/3_30_26_top_hits_to_investigate_hbonds/best_hits_review_4_6_26/269 | D14: PV-005792794357 | E14: ='res269 Ari'!C34 -> yes | F14: ='res269 Ari'!D34 | G14: ='res269 Summer'!C34 -> no | H14: ='res269 Summer'!D34 | I14: no | J14: ='res269 Mary Shay'!D34 | K14: C(NC(=O)C[C@@H](c1ccccc1C)C)[C@H]1CCCN(C(=O)c2cc(N)ccn2)C1 | L14: 3.13442 | M14: =IFERROR(__xludf.DUMMYFUNCTION("IFERROR(REGEXEXTRACT(G14, ""res(269|122)""), ""none"")"),"none") -> none | N14: -15.473368 | O14: 8 | P14: 2 | Q14: 0.375 | R14: 2 | S14: -0.972362 | T14: 100 | U14: 0 | V14: 0 | W14: 95.92927
A15: cp | B15: ../../all/res269/res269_7F16_receptor_only_PV-005904922341_54_3.pdb | C15: /pi/summer.thyme-umw/rosetta_discovery_space/pth2/shapedb_results/refined_conformers/3_30_26_top_hits_to_investigate_hbonds/best_hits_review_4_6_26/269 | D15: PV-005904922341 | E15: ='res269 Ari'!C35 -> yes | F15: ='res269 Ari'!D35 -> I think tyr202 could hbond with the hydroxyl | G15: =#REF! -> #REF! | H15: ='res269 Summer'!D35 | I15: maybe | J15: ='res269 Mary Shay'!D35 | K15: [C@H]1(NC(=O)c2c(ccc(C)n2)C)CCCN(C(=O)C2(CO)CCOCC2)C1 | L15: 1.20834 | M15: =IFERROR(__xludf.DUMMYFUNCTION("IFERROR(REGEXEXTRACT(G15, ""res(269|122)""), ""none"")"),"none") -> none | N15: -15.32929 | O15: 9 | P15: 2 | Q15: 0.444444 | R15: 3 | S15: -1.169854 | T15: 100 | U15: 0 | V15: 0 | W15: 97.9453
A16: cp | B16: ../../all/res269/res269_7F16_receptor_only_PV-006074144815_132_2.pdb | C16: /pi/summer.thyme-umw/rosetta_discovery_space/pth2/shapedb_results/refined_conformers/3_30_26_top_hits_to_investigate_hbonds/best_hits_review_4_6_26/269 | D16: PV-006074144815 | E16: ='res269 Ari'!C40 -> yes | F16: ='res269 Ari'!D40 | G16: ='res269 Summer'!C40 -> no | H16: ='res269 Summer'!D40 | I16: maybe | J16: ='res269 Mary Shay'!D40 | K16: [C@@H]1(N(CC)C(=O)COCC(C)(C)C)CCCN(C(=O)c2ccc(C)c(O)n2)C1 | L16: 2.61142 | M16: =IFERROR(__xludf.DUMMYFUNCTION("IFERROR(REGEXEXTRACT(G16, ""res(269|122)""), ""none"")"),"none") -> none | N16: -16.574584 | O16: 6 | P16: 1 | Q16: 0.333333 | R16: 2 | S16: -0.53138 | T16: 100 | U16: 0 | V16: 0 | W16: 92.227369
A17: cp | B17: ../../all/res269/res269_7F16_receptor_only_PV-006143645773_78_1.pdb | C17: /pi/summer.thyme-umw/rosetta_discovery_space/pth2/shapedb_results/refined_conformers/3_30_26_top_hits_to_investigate_hbonds/best_hits_review_4_6_26/269 | D17: PV-006143645773 | E17: ='res269 Ari'!C41 -> yes | F17: ='res269 Ari'!D41 -> same pose as PV-006143645775 and PV-006143645776, enantiomer | G17: ='res269 Summer'!C41 -> no | H17: ='res269 Summer'!D41 | I17: maybe | J17: ='res269 Mary Shay'!D41 | K17: C(NC(=O)C(C)(C)N1CCCCC1)[C@@H]1CCCN1C(=O)[C@@H](O)C1CCOCC1 | L17: 1.1456 | M17: =IFERROR(__xludf.DUMMYFUNCTION("IFERROR(REGEXEXTRACT(G17, ""res(269|122)""), ""none"")"),"none") -> none | N17: -16.381515 | O17: 6 | P17: 3 | Q17: 0.5 | R17: 2 | S17: -0.391176 | T17: 100 | U17: 0 | V17: 0 | W17: 94.727309
A18: cp | B18: ../../all/res269/res269_7F16_receptor_only_PV-006252057578_235_16.pdb | C18: /pi/summer.thyme-umw/rosetta_discovery_space/pth2/shapedb_results/refined_conformers/3_30_26_top_hits_to_investigate_hbonds/best_hits_review_4_6_26/269 | D18: PV-006252057578 | E18: ='res269 Ari'!C45 -> maybe | F18: ='res269 Ari'!D45 | G18: ='res269 Summer'!C45 -> decent | H18: ='res269 Summer'!D45 | I18: no | J18: ='res269 Mary Shay'!D45 | K18: [C@@H]1(CNC(=O)c2cc3ccccc3c(=O)[nH]2)C[C@H]1CNC(=O)[C@@H]1COCCO1 | L18: 0.4256 | M18: =IFERROR(__xludf.DUMMYFUNCTION("IFERROR(REGEXEXTRACT(G18, ""res(269|122)""), ""none"")"),"none") -> none | N18: -16.196607 | O18: 8 | P18: 5 | Q18: 0.625 | R18: 3 | S18: -1.082057 | T18: 100 | U18: 0 | V18: 0 | W18: 99.346336
A19: cp | B19: ../../all/res269/res269_7F16_receptor_only_PV-006279077450_73_15.pdb | C19: /pi/summer.thyme-umw/rosetta_discovery_space/pth2/shapedb_results/refined_conformers/3_30_26_top_hits_to_investigate_hbonds/best_hits_review_4_6_26/269 | D19: PV-006279077450 | E19: ='res269 Ari'!C47 -> maybe | F19: ='res269 Ari'!D47 | G19: ='res269 Summer'!C47 -> decent | H19: ='res269 Summer'!D47 | I19: no | J19: ='res269 Mary Shay'!D47 | K19: [C@H]1(CCC[C@@H](NC(=O)c2ccc[nH]2)C1)NC(=O)C1(N2CCOCC2)CCCC1 | L19: 1.8169 | M19: =IFERROR(__xludf.DUMMYFUNCTION("IFERROR(REGEXEXTRACT(G19, ""res(269|122)""), ""none"")"),"none") -> none | N19: -17.250811 | O19: 11 | P19: 5 | Q19: 0.272727 | R19: 2 | S19: -0.713731 | T19: 100 | U19: 0 | V19: 0 | W19: 100.30818
A20: cp | B20: ../../all/res269/res269_7F16_receptor_only_PV-006336543198_32_3.pdb | C20: /pi/summer.thyme-umw/rosetta_discovery_space/pth2/shapedb_results/refined_conformers/3_30_26_top_hits_to_investigate_hbonds/best_hits_review_4_6_26/269 | D20: PV-006336543198 | E20: ='res269 Ari'!C49 -> maybe | F20: ='res269 Ari'!D49 | G20: ='res269 Summer'!C49 -> decent | H20: ='res269 Summer'!D49 | I20: maybe | J20: ='res269 Mary Shay'!D49 | K20: C(NC(=O)c1n2nc(C)sc2nc1C)C1(NC(=O)CC2CCCC2)CCC1 | L20: 2.75664 | M20: =IFERROR(__xludf.DUMMYFUNCTION("IFERROR(REGEXEXTRACT(G20, ""res(269|122)""), ""none"")"),"none") -> none | N20: -17.483332 | O20: 7 | P20: 2 | Q20: 0.428571 | R20: 2 | S20: -0.934603 | T20: 100 | U20: 0 | V20: 0 | W20: 93.010636
A21: cp | B21: ../../all/res269/res269_7F16_receptor_only_PV-006596664813_71_2.pdb | C21: /pi/summer.thyme-umw/rosetta_discovery_space/pth2/shapedb_results/refined_conformers/3_30_26_top_hits_to_investigate_hbonds/best_hits_review_4_6_26/269 | D21: PV-006596664813 | E21: ='res269 Ari'!C53 -> maybe | F21: ='res269 Ari'!D53 | G21: ='res269 Summer'!C53 -> decent | H21: ='res269 Summer'!D53 | I21: yes | J21: ='res269 Mary Shay'!D53 | K21: C1(C[C@H](C)NC(=O)c2cn(C)nn2)CN(C(=O)c2c3CC(C)(C)Cc3ccc2)C1 | L21: 2.2205 | M21: =IFERROR(__xludf.DUMMYFUNCTION("IFERROR(REGEXEXTRACT(G21, ""res(269|122)""), ""none"")"),"none") -> none | N21: -15.19198 | O21: 8 | P21: 3 | Q21: 0.375 | R21: 2 | S21: -1.182302 | T21: 100 | U21: 0 | V21: 0 | W21: 97.000718
A22: cp | B22: ../../all/res269/res269_7F16_receptor_only_PV-006598988224_102_4.pdb | C22: /pi/summer.thyme-umw/rosetta_discovery_space/pth2/shapedb_results/refined_conformers/3_30_26_top_hits_to_investigate_hbonds/best_hits_review_4_6_26/269 | D22: PV-006598988224 | E22: ='res269 Ari'!C54 -> maybe | F22: ='res269 Ari'!D54 | G22: ='res269 Summer'!C54 -> yes | H22: ='res269 Summer'!D54 | I22: yes | J22: ='res269 Mary Shay'!D54 | K22: [C@@H]1(NC(=O)CC2CCCC2)CCN(C(=O)c2cc(=O)[nH]nc2)[C@H]1c1ccccc1 | L22: 2.4222 | M22: =IFERROR(__xludf.DUMMYFUNCTION("IFERROR(REGEXEXTRACT(G22, ""res(269|122)""), ""none"")"),"none") -> none | N22: -15.653385 | O22: 8 | P22: 3 | Q22: 0.25 | R22: 2 | S22: -0.166637 | T22: 100 | U22: 0 | V22: 0 | W22: 97.429978
A23: cp | B23: ../../all/res269/res269_7F16_receptor_only_PV-006604268399_13_1.pdb | C23: /pi/summer.thyme-umw/rosetta_discovery_space/pth2/shapedb_results/refined_conformers/3_30_26_top_hits_to_investigate_hbonds/best_hits_review_4_6_26/269 | D23: PV-006604268399 | E23: ='res269 Ari'!C55 -> maybe | F23: ='res269 Ari'!D55 | G23: ='res269 Summer'!C55 -> decent | H23: ='res269 Summer'!D55 | I23: no | J23: ='res269 Mary Shay'!D55 | K23: C1N(CC[C@@H]1CNC(=O)c1c(C)nns1)C(=O)Cc1ccccc1C(C)C | L23: 2.79092 | M23: =IFERROR(__xludf.DUMMYFUNCTION("IFERROR(REGEXEXTRACT(G23, ""res(269|122)""), ""none"")"),"none") -> none | N23: -15.468589 | O23: 8 | P23: 3 | Q23: 0.375 | R23: 2 | S23: -0.987794 | T23: 100 | U23: 0 | V23: 0 | W23: 96.918617
A24: cp | B24: ../../all/res269/res269_7F16_receptor_only_PV-006712468448_190_0.pdb | C24: /pi/summer.thyme-umw/rosetta_discovery_space/pth2/shapedb_results/refined_conformers/3_30_26_top_hits_to_investigate_hbonds/best_hits_review_4_6_26/269 | D24: PV-006712468448 | E24: ='res269 Ari'!C59 -> maybe | F24: ='res269 Ari'!D59 -> same pose as PV-006712468449, enantiomer | G24: ='res269 Summer'!C59 -> decent | H24: ='res269 Summer'!D59 | I24: yes | J24: ='res269 Mary Shay'!D59 | K24: C(=O)(N1C[C@H](NC(=O)C(C)C)[C@@H](C1)C)Cc1ccccc1Oc1ccncc1 | L24: 3.0355 | M24: =IFERROR(__xludf.DUMMYFUNCTION("IFERROR(REGEXEXTRACT(G24, ""res(269|122)""), ""none"")"),"none") -> none | N24: -15.759066 | O24: 7 | P24: 2 | Q24: 0.571429 | R24: 2 | S24: -0.931789 | T24: 100 | U24: 0 | V24: 0 | W24: 94.880574
A25: cp | B25: ../../all/res269/res269_7F16_receptor_only_Z1159218881_192_3.pdb | C25: /pi/summer.thyme-umw/rosetta_discovery_space/pth2/shapedb_results/refined_conformers/3_30_26_top_hits_to_investigate_hbonds/best_hits_review_4_6_26/269 | D25: Z1159218881 | E25: ='res269 Ari'!C63 -> decent | F25: ='res269 Ari'!D63 | G25: ='res269 Summer'!C63 -> no | H25: ='res269 Summer'!D63 | I25: maybe | J25: ='res269 Mary Shay'!D63 | K25: C(=O)(NC(c1ccc(OC)cc1)c1ccc(OC)cc1)CN1CCC(N2CCCC2)CC1 | L25: 3.4696 | M25: =IFERROR(__xludf.DUMMYFUNCTION("IFERROR(REGEXEXTRACT(G25, ""res(269|122)""), ""none"")"),"none") -> none | N25: -16.947939 | O25: 7 | P25: 1 | Q25: 0.285714 | R25: 2 | S25: -1.26662 | T25: 100 | U25: 0 | V25: 0 | W25: 92.071155
A26: cp | B26: ../../all/res269/res269_7F16_receptor_only_Z1634233487_99_4.pdb | C26: /pi/summer.thyme-umw/rosetta_discovery_space/pth2/shapedb_results/refined_conformers/3_30_26_top_hits_to_investigate_hbonds/best_hits_review_4_6_26/269 | D26: Z1634233487 | E26: ='res269 Ari'!C72 -> decent | F26: ='res269 Ari'!D72 | G26: ='res269 Summer'!C72 -> decent | H26: ='res269 Summer'!D72 | I26: maybe | J26: ='res269 Mary Shay'!D72 | K26: N([C@@H]1CCCc2cn(CCOC)nc12)C(=O)c1ccc(S(=O)(=O)N2CCCCC2)o1 | L26: 2.1045 | M26: =IFERROR(__xludf.DUMMYFUNCTION("IFERROR(REGEXEXTRACT(G26, ""res(269|122)""), ""none"")"),"none") -> none | N26: -16.284917 | O26: 8 | P26: 5 | Q26: 0.25 | R26: 2 | S26: -1.566179 | T26: 100 | U26: 0 | V26: 0 | W26: 97.398904
A27: cp | B27: ../../all/res269/res269_7F16_receptor_only_Z1998434183_30_67.pdb | C27: /pi/summer.thyme-umw/rosetta_discovery_space/pth2/shapedb_results/refined_conformers/3_30_26_top_hits_to_investigate_hbonds/best_hits_review_4_6_26/269 | D27: Z1998434183 | E27: ='res269 Ari'!C73 -> maybe | F27: ='res269 Ari'!D73 | G27: ='res269 Summer'!C73 -> decent | H27: ='res269 Summer'!D73 | I27: no | J27: ='res269 Mary Shay'!D73 | K27: C(=O)([C@@H](CC(C)C)NC1=NS(=O)(=O)c2ccccc12)N[C@@H](CCO)Cc1ccccc1 | L27: 2.2497 | M27: =IFERROR(__xludf.DUMMYFUNCTION("IFERROR(REGEXEXTRACT(G27, ""res(269|122)""), ""none"")"),"none") -> none | N27: -16.118663 | O27: 9 | P27: 1 | Q27: 0.333333 | R27: 2 | S27: -0.368431 | T27: 100 | U27: 0 | V27: 0 | W27: 95.846239
A28: cp | B28: ../../all/res269/res269_7F16_receptor_only_Z395775478_134_52.pdb | C28: /pi/summer.thyme-umw/rosetta_discovery_space/pth2/shapedb_results/refined_conformers/3_30_26_top_hits_to_investigate_hbonds/best_hits_review_4_6_26/269 | D28: Z395775478 | E28: ='res269 Ari'!C77 -> maybe | F28: ='res269 Ari'!D77 -> unsatisfied sulfonamide O is probably bad | G28: ='res269 Summer'!C77 -> decent | H28: ='res269 Summer'!D77 | I28: no | J28: ='res269 Mary Shay'!D77 | K28: C(CNS(=O)(=O)c1ccc(C)cc1)C(=O)N1CCCC[C@H]1CNS(=O)(=O)C | L28: 0.59372 | M28: =IFERROR(__xludf.DUMMYFUNCTION("IFERROR(REGEXEXTRACT(G28, ""res(269|122)""), ""none"")"),"none") -> none | N28: -15.935374 | O28: 10 | P28: 2 | Q28: 0.3 | R28: 3 | S28: -1.849118 | T28: 100 | U28: 0 | V28: 0 | W28: 97.515508
A29: cp | B29: ../../all/res269/res269_7F16_receptor_only_Z4322826053_15_0.pdb | C29: /pi/summer.thyme-umw/rosetta_discovery_space/pth2/shapedb_results/refined_conformers/3_30_26_top_hits_to_investigate_hbonds/best_hits_review_4_6_26/269 | D29: Z4322826053 | E29: ='res269 Ari'!C78 -> decent | F29: ='res269 Ari'!D78 -> same pose as Z4322826055, enantiomer | G29: ='res269 Summer'!C78 -> no | H29: ='res269 Summer'!D78 | I29: no | J29: ='res269 Mary Shay'!D78 | K29: c1(C(=O)N[C@H](CC(=O)O)C2CCCCC2)cccc(C(=O)N2CCCCC2)c1 | L29: 3.4661 | M29: =IFERROR(__xludf.DUMMYFUNCTION("IFERROR(REGEXEXTRACT(G29, ""res(269|122)""), ""none"")"),"none") -> none | N29: -15.953649 | O29: 12 | P29: 5 | Q29: 0.416667 | R29: 3 | S29: -0.584621 | T29: 100 | U29: 0 | V29: 0 | W29: 103.8784
A30: cp | B30: ../../all/res269/res269_7F16_receptor_only_Z4322826055_15_0.pdb | C30: /pi/summer.thyme-umw/rosetta_discovery_space/pth2/shapedb_results/refined_conformers/3_30_26_top_hits_to_investigate_hbonds/best_hits_review_4_6_26/269 | D30: Z4322826055 | E30: ='res269 Ari'!C79 -> decent | F30: ='res269 Ari'!D79 -> same pose as Z4322826053, enantiomer | G30: ='res269 Summer'!C79 -> no | H30: ='res269 Summer'!D79 | I30: no | J30: ='res269 Mary Shay'!D79 | K30: c1(C(=O)N[C@H](CC(=O)O)C2CCCCC2)cccc(C(=O)N2CCCCC2)c1 | L30: 3.4661 | M30: =IFERROR(__xludf.DUMMYFUNCTION("IFERROR(REGEXEXTRACT(G30, ""res(269|122)""), ""none"")"),"none") -> none | N30: -15.953649 | O30: 12 | P30: 5 | Q30: 0.416667 | R30: 3 | S30: -0.584621 | T30: 100 | U30: 0 | V30: 0 | W30: 103.8784
A31: cp | B31: ../../all/res269/res269_7F16_receptor_only_Z4881795942_226_8.pdb | C31: /pi/summer.thyme-umw/rosetta_discovery_space/pth2/shapedb_results/refined_conformers/3_30_26_top_hits_to_investigate_hbonds/best_hits_review_4_6_26/269 | D31: Z4881795942 | E31: ='res269 Ari'!C81 -> maybe | F31: ='res269 Ari'!D81 -> same pose as Z4881795915, enantiomer | G31: ='res269 Summer'!C81 -> decent | H31: ='res269 Summer'!D81 | I31: maybe | J31: ='res269 Mary Shay'!D81 | K31: N1(CCC[C@@H](NC(=O)[C@H]2CCC(=O)NC2)C1)C(=O)[C@@H]1CCC(=O)N(c2cc(F)ccc2)C1 | L31: 1.2021 | M31: =IFERROR(__xludf.DUMMYFUNCTION("IFERROR(REGEXEXTRACT(G31, ""res(269|122)""), ""none"")"),"none") -> none | N31: -15.47128 | O31: 8 | P31: 5 | Q31: 0.5 | R31: 2 | S31: -0.38008 | T31: 100 | U31: 0 | V31: 0 | W31: 99.64864
G32: ='res269 Summer (old)'!C86 | H32: ='res269 Summer (old)'!D86 | I32: ='res269 Mary Shay'!C86 | J32: ='res269 Mary Shay'!D86
G33: ='res269 Summer (old)'!C87 | H33: ='res269 Summer (old)'!D87 | I33: ='res269 Mary Shay'!C87 | J33: ='res269 Mary Shay'!D87
G34: ='res269 Summer (old)'!C88 | H34: ='res269 Summer (old)'!D88 | I34: ='res269 Mary Shay'!C88 | J34: ='res269 Mary Shay'!D88
G35: ='res269 Summer (old)'!C89 | H35: ='res269 Summer (old)'!D89 | I35: ='res269 Mary Shay'!C89 | J35: ='res269 Mary Shay'!D89
G36: ='res269 Summer (old)'!C90 | H36: ='res269 Summer (old)'!D90 | I36: ='res269 Mary Shay'!C90 | J36: ='res269 Mary Shay'!D90
G37: ='res269 Summer (old)'!C91 | H37: ='res269 Summer (old)'!D91 | I37: ='res269 Mary Shay'!C91 | J37: ='res269 Mary Shay'!D91
G38: ='res269 Summer (old)'!C92 | H38: ='res269 Summer (old)'!D92 | I38: ='res269 Mary Shay'!C92 | J38: ='res269 Mary Shay'!D92
G39: ='res269 Summer (old)'!C93 | H39: ='res269 Summer (old)'!D93 | I39: ='res269 Mary Shay'!C93 | J39: ='res269 Mary Shay'!D93
G40: ='res269 Summer (old)'!C94 | H40: ='res269 Summer (old)'!D94 | I40: ='res269 Mary Shay'!C94 | J40: ='res269 Mary Shay'!D94
...

Sheet res122 All Thoughts
A1: file | B1: ligand_name | C1: Does Ari Like? | D1: Comments | E1: Does Summer Like? | F1: Comments | G1: Does Mary Shay Like? | H1: Comments | I1: anchor | J1: ddg | K1: total_motifs | L1: significant_motifs | M1: real_motif_ratio | N1: hbond_motif_count | O1: hbond_motif_energy_sum | P1: closest_autodock_recovery_rmsd | Q1: closest_autodock_recovery_ddg | R1: strain_energy | S1: total
A2: /pi/summer.thyme-umw/rosetta_discovery_space/pth2/shapedb_results/refined_conformers/lower_res1_11_shifted/0/PV-003476110573/122/placement/res122_7F16_receptor_only_PV-003476110573_20_3.pdb | B2: PV-003476110573 | C2: ='res122 Ari'!C2 -> maybe | D2: ='res122 Ari'!D2 -> probably reject over how it hits arg160 and asn402 | E2: ='res122 Summer'!C2 -> yes | F2: ='res122 Summer'!D2 | G2: ='res122 Mary Shay'!C2 | H2: ='res122 Mary Shay'!D2 | I2: =IFERROR(__xludf.DUMMYFUNCTION("IFERROR(REGEXEXTRACT(E2, ""res(269|122)""), ""none"")"),"none") -> none | J2: -15.535781 | K2: 9 | L2: 3 | M2: 0.444444 | N2: 2 | O2: -1.719191 | P2: 100 | Q2: 0 | R2: 0 | S2: 97.189472
A3: /pi/summer.thyme-umw/rosetta_discovery_space/pth2/shapedb_results/refined_conformers/lower_res5_11_shifted/7/PV-004363072660/122/placement/res122_7F16_receptor_only_PV-004363072660_208_3.pdb | B3: PV-004363072660 | C3: ='res122 Ari'!C3 -> maybe | D3: ='res122 Ari'!D3 -> not best around middle and has ester | E3: ='res122 Summer'!C3 -> no | F3: ='res122 Summer'!D3 | G3: ='res122 Mary Shay'!C3 | H3: ='res122 Mary Shay'!D3 | I3: =IFERROR(__xludf.DUMMYFUNCTION("IFERROR(REGEXEXTRACT(E3, ""res(269|122)""), ""none"")"),"none") -> none | J3: -17.372141 | K3: 10 | L3: 2 | M3: 0.3 | N3: 2 | O3: -1.446995 | P3: 100 | Q3: 0 | R3: 0 | S3: 95.480864
A4: /pi/summer.thyme-umw/rosetta_discovery_space/pth2/shapedb_results/refined_conformers/lower_res5_11_shifted/4/PV-004434805041/122/placement/res122_7F16_receptor_only_PV-004434805041_203_1.pdb | B4: PV-004434805041 | C4: ='res122 Ari'!C4 -> maybe | D4: ='res122 Ari'!D4 -> probably bad, but I do kind of like how it snakes up and interaction with TYR122 is apparently real. carbonyl into val191 is probably really bad | E4: ='res122 Summer'!C4 -> no | F4: ='res122 Summer'!D4 | G4: ='res122 Mary Shay'!C4 | H4: ='res122 Mary Shay'!D4 | I4: =IFERROR(__xludf.DUMMYFUNCTION("IFERROR(REGEXEXTRACT(E4, ""res(269|122)""), ""none"")"),"none") -> none | J4: -15.13854 | K4: 9 | L4: 4 | M4: 0.333333 | N4: 2 | O4: -1.065005 | P4: 100 | Q4: 0 | R4: 0 | S4: 99.129788
A5: /pi/summer.thyme-umw/rosetta_discovery_space/pth2/shapedb_results/refined_conformers/lower_res1_11_shifted/16/PV-004444948705/122/placement/res122_7F16_receptor_only_PV-004444948705_47_1.pdb | B5: PV-004444948705 | C5: ='res122 Ari'!C5 -> maybe | D5: ='res122 Ari'!D5 -> could maybe flex to hit glu398 | E5: ='res122 Summer'!C5 -> maybe | F5: ='res122 Summer'!D5 | G5: ='res122 Mary Shay'!C5 | H5: ='res122 Mary Shay'!D5 | I5: =IFERROR(__xludf.DUMMYFUNCTION("IFERROR(REGEXEXTRACT(E5, ""res(269|122)""), ""none"")"),"none") -> none | J5: -15.55909 | K5: 12 | L5: 4 | M5: 0.25 | N5: 2 | O5: -0.857348 | P5: 100 | Q5: 0 | R5: 0 | S5: 101.83356
A6: /pi/summer.thyme-umw/rosetta_discovery_space/pth2/shapedb_results/refined_conformers/lower_res1_11_shifted/24/PV-004502754221/122/placement/res122_7F16_receptor_only_PV-004502754221_27_2.pdb | B6: PV-004502754221 | C6: ='res122 Ari'!C6 -> maybe | D6: ='res122 Ari'!D6 -> if tyr122 H moves, could form hbond | E6: ='res122 Summer'!C6 -> no | F6: ='res122 Summer'!D6 | G6: ='res122 Mary Shay'!C6 | H6: ='res122 Mary Shay'!D6 | I6: =IFERROR(__xludf.DUMMYFUNCTION("IFERROR(REGEXEXTRACT(E6, ""res(269|122)""), ""none"")"),"none") -> none | J6: -16.502904 | K6: 8 | L6: 3 | M6: 0.25 | N6: 3 | O6: -0.998347 | P6: 100 | Q6: 0 | R6: 0 | S6: 96.748749
A7: /pi/summer.thyme-umw/rosetta_discovery_space/pth2/shapedb_results/refined_conformers/lower_res1_11_shifted/30/PV-004506477178/122/placement/res122_7F16_receptor_only_PV-004506477178_31_0.pdb | B7: PV-004506477178 | C7: ='res122 Ari'!C7 -> decent | D7: ='res122 Ari'!D7 -> it's bendy, but I like how it hits overall. check strain score | E7: ='res122 Summer'!C7 -> decent | F7: ='res122 Summer'!D7 | G7: ='res122 Mary Shay'!C7 | H7: ='res122 Mary Shay'!D7 | I7: =IFERROR(__xludf.DUMMYFUNCTION("IFERROR(REGEXEXTRACT(E7, ""res(269|122)""), ""none"")"),"none") -> none | J7: -16.222639 | K7: 10 | L7: 3 | M7: 0.3 | N7: 2 | O7: -1.763647 | P7: 100 | Q7: 0 | R7: 0 | S7: 97.313714
A8: /pi/summer.thyme-umw/rosetta_discovery_space/pth2/shapedb_results/refined_conformers/lower_res1_11_shifted/18/PV-004506718703/122/placement/res122_7F16_receptor_only_PV-004506718703_31_1.pdb | B8: PV-004506718703 | C8: ='res122 Ari'!C8 -> maybe | D8: ='res122 Ari'!D8 -> misses res122 but pose looks not terrible | E8: ='res122 Summer'!C8 -> decent | F8: ='res122 Summer'!D8 | G8: ='res122 Mary Shay'!C8 | H8: ='res122 Mary Shay'!D8 | I8: =IFERROR(__xludf.DUMMYFUNCTION("IFERROR(REGEXEXTRACT(E8, ""res(269|122)""), ""none"")"),"none") -> none | J8: -15.296063 | K8: 8 | L8: 3 | M8: 0.25 | N8: 2 | O8: -1.293353 | P8: 100 | Q8: 0 | R8: 0 | S8: 96.660584
A9: /pi/summer.thyme-umw/rosetta_discovery_space/pth2/shapedb_results/refined_conformers/lower_res1_11_shifted/1/PV-004576257327/122/placement/res122_7F16_receptor_only_PV-004576257327_176_5.pdb | B9: PV-004576257327 | C9: ='res122 Ari'!C9 -> decent | D9: ='res122 Ari'!D9 | E9: ='res122 Summer'!C9 -> no | F9: ='res122 Summer'!D9 | G9: ='res122 Mary Shay'!C9 | H9: ='res122 Mary Shay'!D9 | I9: =IFERROR(__xludf.DUMMYFUNCTION("IFERROR(REGEXEXTRACT(E9, ""res(269|122)""), ""none"")"),"none") -> none | J9: -15.047575 | K9: 8 | L9: 4 | M9: 0.25 | N9: 2 | O9: -1.824829 | P9: 100 | Q9: 0 | R9: 0 | S9: 97.377596
A10: /pi/summer.thyme-umw/rosetta_discovery_space/pth2/shapedb_results/refined_conformers/lower_res1_11_shifted/23/PV-004655902680/122/placement/res122_7F16_receptor_only_PV-004655902680_26_5.pdb | B10: PV-004655902680 | C10: ='res122 Ari'!C10 -> decent | D10: ='res122 Ari'!D10 -> can carbonyl point into tyrosine like into a benzene? | E10: ='res122 Summer'!C10 -> yes | F10: ='res122 Summer'!D10 | G10: ='res122 Mary Shay'!C10 | H10: ='res122 Mary Shay'!D10 | I10: =IFERROR(__xludf.DUMMYFUNCTION("IFERROR(REGEXEXTRACT(E10, ""res(269|122)""), ""none"")"),"none") -> none | J10: -15.950047 | K10: 7 | L10: 3 | M10: 0.285714 | N10: 3 | O10: -1.505897 | P10: 100 | Q10: 0 | R10: 0 | S10: 95.82977
A11: /pi/summer.thyme-umw/rosetta_discovery_space/pth2/shapedb_results/refined_conformers/lower_res1_11_shifted/17/PV-004798493641/122/placement/res122_7F16_receptor_only_PV-004798493641_166_0.pdb | B11: PV-004798493641 | C11: ='res122 Ari'!C11 -> maybe | D11: ='res122 Ari'!D11 -> I like binding profile at bottom, but ASN402 could be a problem | E11: ='res122 Summer'!C11 -> maybe | F11: ='res122 Summer'!D11 | G11: ='res122 Mary Shay'!C11 | H11: ='res122 Mary Shay'!D11 | I11: =IFERROR(__xludf.DUMMYFUNCTION("IFERROR(REGEXEXTRACT(E11, ""res(269|122)""), ""none"")"),"none") -> none | J11: -15.642859 | K11: 11 | L11: 3 | M11: 0.272727 | N11: 2 | O11: -1.1816 | P11: 100 | Q11: 0 | R11: 0 | S11: 99.448268
A12: /pi/summer.thyme-umw/rosetta_discovery_space/pth2/shapedb_results/refined_conformers/lower_res5_11_shifted/1/PV-004887538871/122/placement/res122_7F16_receptor_only_PV-004887538871_10_3.pdb | B12: PV-004887538871 | C12: ='res122 Ari'!C12 -> maybe | D12: ='res122 Ari'!D12 -> not great against tyr122 | E12: ='res122 Summer'!C12 -> decent | F12: ='res122 Summer'!D12 | G12: ='res122 Mary Shay'!C12 | H12: ='res122 Mary Shay'!D12 | I12: =IFERROR(__xludf.DUMMYFUNCTION("IFERROR(REGEXEXTRACT(E12, ""res(269|122)""), ""none"")"),"none") -> none | J12: -15.476613 | K12: 12 | L12: 4 | M12: 0.333333 | N12: 2 | O12: -0.623346 | P12: 100 | Q12: 0 | R12: 0 | S12: 102.23337
A13: /pi/summer.thyme-umw/rosetta_discovery_space/pth2/shapedb_results/refined_conformers/lower_res5_11_shifted/10/PV-004894803557/122/placement/res122_7F16_receptor_only_PV-004894803557_120_3.pdb | B13: PV-004894803557 | C13: ='res122 Ari'!C13 -> decent | D13: ='res122 Ari'!D13 | E13: ='res122 Summer'!C13 -> no | F13: ='res122 Summer'!D13 | G13: ='res122 Mary Shay'!C13 | H13: ='res122 Mary Shay'!D13 | I13: =IFERROR(__xludf.DUMMYFUNCTION("IFERROR(REGEXEXTRACT(E13, ""res(269|122)""), ""none"")"),"none") -> none | J13: -16.216217 | K13: 7 | L13: 4 | M13: 0.285714 | N13: 2 | O13: -0.930066 | P13: 100 | Q13: 0 | R13: 0 | S13: 96.139431
A14: /pi/summer.thyme-umw/rosetta_discovery_space/pth2/shapedb_results/refined_conformers/lower_res1_11_shifted/17/PV-004938971812/122/placement/res122_7F16_receptor_only_PV-004938971812_58_0.pdb | B14: PV-004938971812 | C14: ='res122 Ari'!C14 -> maybe | D14: ='res122 Ari'!D14 | E14: ='res122 Summer'!C14 -> no | F14: ='res122 Summer'!D14 | G14: ='res122 Mary Shay'!C14 | H14: ='res122 Mary Shay'!D14 | I14: =IFERROR(__xludf.DUMMYFUNCTION("IFERROR(REGEXEXTRACT(E14, ""res(269|122)""), ""none"")"),"none") -> none | J14: -15.113702 | K14: 8 | L14: 3 | M14: 0.25 | N14: 2 | O14: -0.761492 | P14: 100 | Q14: 0 | R14: 0 | S14: 97.374806
A15: /pi/summer.thyme-umw/rosetta_discovery_space/pth2/shapedb_results/refined_conformers/lower_res5_11_shifted/2/PV-004986901707/122/placement/res122_7F16_receptor_only_PV-004986901707_31_1.pdb | B15: PV-004986901707 | C15: ='res122 Ari'!C15 -> maybe | D15: ='res122 Ari'!D15 -> carbonyl in middle could maybe hit water? | E15: ='res122 Summer'!C15 -> no | F15: ='res122 Summer'!D15 | G15: ='res122 Mary Shay'!C15 | H15: ='res122 Mary Shay'!D15 | I15: =IFERROR(__xludf.DUMMYFUNCTION("IFERROR(REGEXEXTRACT(E15, ""res(269|122)""), ""none"")"),"none") -> none | J15: -15.419001 | K15: 8 | L15: 5 | M15: 0.5 | N15: 3 | O15: -1.097048 | P15: 100 | Q15: 0 | R15: 0 | S15: 99.983951
A16: /pi/summer.thyme-umw/rosetta_discovery_space/pth2/shapedb_results/refined_conformers/lower_res1_11_shifted/0/PV-005198202028/122/placement/res122_7F16_receptor_only_PV-005198202028_82_1.pdb | B16: PV-005198202028 | C16: ='res122 Ari'!C16 -> maybe | D16: ='res122 Ari'!D16 -> phe194 interaction could be bad | E16: ='res122 Summer'!C16 -> maybe | F16: ='res122 Summer'!D16 | G16: ='res122 Mary Shay'!C16 | H16: ='res122 Mary Shay'!D16 | I16: =IFERROR(__xludf.DUMMYFUNCTION("IFERROR(REGEXEXTRACT(E16, ""res(269|122)""), ""none"")"),"none") -> none | J16: -15.695975 | K16: 7 | L16: 5 | M16: 0.428571 | N16: 2 | O16: -0.51858 | P16: 100 | Q16: 0 | R16: 0 | S16: 98.214016
A17: /pi/summer.thyme-umw/rosetta_discovery_space/pth2/shapedb_results/refined_conformers/lower_res1_11_shifted/2/PV-005424082445/122/placement/res122_7F16_receptor_only_PV-005424082445_136_0.pdb | B17: PV-005424082445 | C17: ='res122 Ari'!C17 -> maybe | D17: ='res122 Ari'!D17 | E17: ='res122 Summer'!C17 -> decent | F17: ='res122 Summer'!D17 | G17: ='res122 Mary Shay'!C17 | H17: ='res122 Mary Shay'!D17 | I17: =IFERROR(__xludf.DUMMYFUNCTION("IFERROR(REGEXEXTRACT(E17, ""res(269|122)""), ""none"")"),"none") -> none | J17: -15.040718 | K17: 6 | L17: 3 | M17: 0.333333 | N17: 2 | O17: -1.138986 | P17: 100 | Q17: 0 | R17: 0 | S17: 95.153629
